
<sdf version="1.6">
    <model name="crazyflie">
        <pose>0 0 0.0 0 0 3.14</pose>
        <link name="crazyflie/body">
            <inertial>
                <pose>0 0 0 0 0 0</pose>
                <mass>0.025</mass>
                <inertia>
                    <ixx>0.000016572</ixx>
                    <ixy>0.00</ixy>
                    <ixz>0.00</ixz>
                    <iyy>0.000016656</iyy>
                    <iyz>0.00000</iyz>
                    <izz>0.000029262</izz>
                </inertia>
            </inertial>
            <collision name="crazyflie/body_collision">
                <pose>0 0 0.015 0 0 0</pose>
                <geometry>
                    <box>
                        <size>0.10 0.10 0.03</size>
                    </box>
                </geometry>
            </collision>
            <visual name="crazyflie/body_visual">
                <pose>0 0 0 0 -0 0</pose>
                <geometry>
                    <mesh>
                        <scale>1 1 1</scale>
                        <uri>model://iris_crazyflie/meshes/cf2_assembly.dae</uri>
                    </mesh>
                </geometry>
            </visual>
            <gravity>1</gravity>
            <velocity_decay/>
        </link>
        <link name='/imu_link'>
            <pose>0 0 0 0 0 0</pose>
            <inertial>
                <pose>0 0 0 0 0 0</pose>
                <mass>0.015</mass>
                <inertia>
                    <ixx>1e-05</ixx>
                    <ixy>0</ixy>
                    <ixz>0</ixz>
                    <iyy>1e-05</iyy>
                    <iyz>0</iyz>
                    <izz>1e-05</izz>
                </inertia>
            </inertial>
        </link>
        <joint name='/imu_joint' type='revolute'>
            <child>/imu_link</child>
            <parent>crazyflie/body</parent>
            <axis>
                <xyz>1 0 0</xyz>
                <limit>
                <lower>0</lower>
                <upper>0</upper>
                <effort>0</effort>
                <velocity>0</velocity>
                </limit>
                <dynamics>
                <spring_reference>0</spring_reference>
                <spring_stiffness>0</spring_stiffness>
                </dynamics>
                <use_parent_model_frame>1</use_parent_model_frame>
            </axis>
        </joint>
        <link name="crazyflie/m1_prop">
            <pose>0.031 -0.031 0.021 0 0 0</pose>
            <inertial>
                <pose>0 0 0 0 -0 0</pose>
                <mass>0.0008</mass>
                <inertia>
                    <ixx>0.000000002*70</ixx>
                    <iyy>0.000000167*70</iyy>
                    <izz>0.000000168*70</izz>
                    <ixy>0</ixy>
                    <ixz>0</ixz>
                    <iyz>0</iyz>
                </inertia>
            </inertial>
            <visual name="crazyflie/m1_visual">
                <pose>0 0 0 0 -0 0</pose>
                <geometry>
                    <mesh>
                        <scale>1 1 1</scale>
                        <uri>model://iris_crazyflie/meshes/ccw_prop.dae</uri>
                    </mesh>
                </geometry>
            </visual>
            <gravity>1</gravity>
            <velocity_decay/>
        </link>
        <link name="crazyflie/m2_prop">
            <pose>-0.031 -0.031 0.021 0 0 0</pose>
            <inertial>
                <pose>0 0 0 0 -0 0</pose>
                <mass>0.0008</mass>
                <inertia>
                    <ixx>0.000000002*50</ixx>
                    <iyy>0.000000167*50</iyy>
                    <izz>0.000000168*50</izz>
                    <ixy>0</ixy>
                    <ixz>0</ixz>
                    <iyz>0</iyz>
                </inertia>
            </inertial>
            <visual name="crazyflie/m2_visual">
                <pose>0 0 0 0 -0 0</pose>
                <geometry>
                    <mesh>
                        <scale>1 1 1</scale>
                        <uri>model://iris_crazyflie/meshes/cw_prop.dae</uri>
                    </mesh>
                </geometry>
            </visual>
            <gravity>1</gravity>
            <velocity_decay/>
        </link>
        <link name="crazyflie/m3_prop">
            <pose >-0.031 0.031 0.021 0 0 0</pose>
            <inertial>
                <pose>0 0 0 0 -0 0</pose>
                <mass>0.0008</mass>
                <inertia>
                    <ixx>0.000000002*50</ixx>
                    <iyy>0.000000167*50</iyy>
                    <izz>0.000000168*50</izz>
                    <ixy>0</ixy>
                    <ixz>0</ixz>
                    <iyz>0</iyz>
                </inertia>
            </inertial>
            <visual name="crazyflie/m3_visual">
                <pose>0 0 0 0 -0 0</pose>
                <geometry>
                    <mesh>
                        <scale>1 1 1</scale>
                        <uri>model://iris_crazyflie/meshes/ccw_prop.dae</uri>
                    </mesh>
                </geometry>
            </visual>
            <gravity>1</gravity>
            <velocity_decay/>
        </link>
        <link name="crazyflie/m4_prop">
            <pose>0.031 0.031 0.021 0 0 0</pose>
            <inertial>
                <pose>0 0 0 0 -0 0</pose>
                <mass>0.0008</mass>
                <inertia>
                    <ixx>0.000000002*50</ixx>
                    <iyy>0.000000167*50</iyy>
                    <izz>0.000000168*50</izz>
                    <ixy>0</ixy>
                    <ixz>0</ixz>
                    <iyz>0</iyz>
                </inertia>
            </inertial>
            <visual name="crazyflie/m4_visual">
                <pose>0 0 0 0 -0 0</pose>
                <geometry>
                    <mesh>
                        <scale>1 1 1</scale>
                        <uri>model://iris_crazyflie/meshes/cw_prop.dae</uri>
                    </mesh>
                </geometry>
            </visual>
            <gravity>1</gravity>
            <velocity_decay/>
        </link>
        <joint name="crazyflie/m1_joint" type="revolute">
            <child>crazyflie/m1_prop</child>
            <parent>crazyflie/body</parent>
            <axis>
                <xyz>0 0 1</xyz>
                <limit>
                    <lower>-1e+16</lower>
                    <upper>1e+16</upper>
                </limit>
                <dynamics>
                    <spring_reference>0</spring_reference>
                    <spring_stiffness>0</spring_stiffness>
                </dynamics>
                <use_parent_model_frame>1</use_parent_model_frame>
            </axis>
        </joint>
                <joint name="crazyflie/m2_joint" type="revolute">
            <child>crazyflie/m2_prop</child>
            <parent>crazyflie/body</parent>
            <axis>
                <xyz>0 0 1</xyz>
                <limit>
                    <lower>-1e+16</lower>
                    <upper>1e+16</upper>
                </limit>
                <dynamics>
                    <spring_reference>0</spring_reference>
                    <spring_stiffness>0</spring_stiffness>
                </dynamics>
                <use_parent_model_frame>1</use_parent_model_frame>
            </axis>
        </joint>
                <joint name="crazyflie/m3_joint" type="revolute">
            <child>crazyflie/m3_prop</child>
            <parent>crazyflie/body</parent>
            <axis>
                <xyz>0 0 1</xyz>
                <limit>
                    <lower>-1e+16</lower>
                    <upper>1e+16</upper>
                </limit>
                <dynamics>
                    <spring_reference>0</spring_reference>
                    <spring_stiffness>0</spring_stiffness>
                </dynamics>
                <use_parent_model_frame>1</use_parent_model_frame>
            </axis>
        </joint>
        <joint name="crazyflie/m4_joint" type="revolute">
            <child>crazyflie/m4_prop</child>
            <parent>crazyflie/body</parent>
            <axis>
                <xyz>0 0 1</xyz>
                <limit>
                    <lower>-1e+16</lower>
                    <upper>1e+16</upper>
                </limit>
                <dynamics>
                    <spring_reference>0</spring_reference>
                    <spring_stiffness>0</spring_stiffness>
                </dynamics>
                <use_parent_model_frame>1</use_parent_model_frame>
            </axis>
        </joint>


        <plugin name='rosbag' filename='libgazebo_multirotor_base_plugin.so'>
            <robotNamespace/>
            <linkName>crazyflie/body</linkName>
            <rotorVelocitySlowdownSim>150</rotorVelocitySlowdownSim>
        </plugin>
        <plugin name='front_right_motor_model' filename='libgazebo_motor_model.so'>
            <robotNamespace/>
            <jointName>crazyflie/m1_joint</jointName>
            <linkName>crazyflie/m1_prop</linkName>
            <turningDirection>ccw</turningDirection>
            <timeConstantUp>0.0125</timeConstantUp>
            <timeConstantDown>0.025</timeConstantDown>
            <maxRotVelocity>2618</maxRotVelocity>
            <motorConstant>1.28192e-08</motorConstant>
            <momentConstant>0.005964552</momentConstant>
            <commandSubTopic>/gazebo/command/motor_speed</commandSubTopic>
            <motorNumber>0</motorNumber>
            <rotorDragCoefficient>8.06428e-05</rotorDragCoefficient>
            <rollingMomentCoefficient>0.0000001</rollingMomentCoefficient>
            <motorSpeedPubTopic>/motor_speed/0</motorSpeedPubTopic>
            <rotorVelocitySlowdownSim>150</rotorVelocitySlowdownSim>
            <motorType>velocity</motorType>
        </plugin>

        <plugin name='back_right_motor_model' filename='libgazebo_motor_model.so'>
            <robotNamespace/>
            <jointName>crazyflie/m2_joint</jointName>
            <linkName>crazyflie/m2_prop</linkName>
            <turningDirection>cw</turningDirection>
            <timeConstantUp>0.0125</timeConstantUp>
            <timeConstantDown>0.025</timeConstantDown>
            <maxRotVelocity>2618</maxRotVelocity>
            <motorConstant>1.28192e-08</motorConstant>
            <momentConstant>0.005964552</momentConstant>
            <commandSubTopic>/gazebo/command/motor_speed</commandSubTopic>
            <motorNumber>1</motorNumber>
            <rotorDragCoefficient>8.06428e-05</rotorDragCoefficient>
            <rollingMomentCoefficient>0.0000001</rollingMomentCoefficient>
            <motorSpeedPubTopic>/motor_speed/1</motorSpeedPubTopic>
            <rotorVelocitySlowdownSim>150</rotorVelocitySlowdownSim>
            <motorType>velocity</motorType>
        </plugin>
        <plugin name='back_left_motor_model' filename='libgazebo_motor_model.so'>
        <robotNamespace/>
            <jointName>crazyflie/m3_joint</jointName>
            <linkName>crazyflie/m3_prop</linkName>
            <turningDirection>ccw</turningDirection>
            <timeConstantUp>0.0125</timeConstantUp>
            <timeConstantDown>0.025</timeConstantDown>
            <maxRotVelocity>2618</maxRotVelocity>
            <motorConstant>1.28192e-08</motorConstant>
            <momentConstant>0.005964552</momentConstant>
            <commandSubTopic>/gazebo/command/motor_speed</commandSubTopic>
            <motorNumber>2</motorNumber>
            <rotorDragCoefficient>8.06428e-05</rotorDragCoefficient>
            <rollingMomentCoefficient>0.0000001</rollingMomentCoefficient>
            <motorSpeedPubTopic>/motor_speed/2</motorSpeedPubTopic>
            <rotorVelocitySlowdownSim>150</rotorVelocitySlowdownSim>
            <motorType>velocity</motorType>
        </plugin>


        <plugin name='front_left_motor_model' filename='libgazebo_motor_model.so'>
        <robotNamespace/>
            <jointName>crazyflie/m4_joint</jointName>
            <linkName>crazyflie/m4_prop</linkName>
            <turningDirection>cw</turningDirection>
            <timeConstantUp>0.0125</timeConstantUp>
            <timeConstantDown>0.025</timeConstantDown>
            <maxRotVelocity>2618</maxRotVelocity>
            <motorConstant>1.28192e-08</motorConstant>
            <momentConstant>0.005964552</momentConstant>
            <commandSubTopic>/gazebo/command/motor_speed</commandSubTopic>
            <motorNumber>3</motorNumber>
            <rotorDragCoefficient>8.06428e-05</rotorDragCoefficient>
            <rollingMomentCoefficient>0.000001</rollingMomentCoefficient>
            <motorSpeedPubTopic>/motor_speed/3</motorSpeedPubTopic>
            <rotorVelocitySlowdownSim>150</rotorVelocitySlowdownSim>
            <motorType>velocity</motorType>
        </plugin>

        <include>
            <uri>model://gps</uri>
            <pose>0.0 0.0 0.03 0 0 0</pose>
            <name>gps0</name>
        </include>
        <joint name='gps0_joint' type='fixed'>
            <child>gps0::link</child>
            <parent>crazyflie/body</parent>
        </joint>

        <plugin name='groundtruth_plugin' filename='libgazebo_groundtruth_plugin.so'>
            <robotNamespace/>
        </plugin>
        <plugin name='magnetometer_plugin' filename='libgazebo_magnetometer_plugin.so'>
            <robotNamespace/>
            <pubRate>100</pubRate>
            <noiseDensity>0.0004</noiseDensity>
            <randomWalk>6.4e-06</randomWalk>
            <biasCorrelationTime>600</biasCorrelationTime>
            <magTopic>/mag</magTopic>
        </plugin>
        <plugin name='barometer_plugin' filename='libgazebo_barometer_plugin.so'>
            <robotNamespace/>
            <pubRate>50</pubRate>
            <baroTopic>/baro</baroTopic>
            <baroDriftPaPerSec>0</baroDriftPaPerSec>
        </plugin>
        <plugin name='mavlink_interface' filename='libgazebo_mavlink_interface.so'>
            <robotNamespace/>
            <imuSubTopic>/imu</imuSubTopic>
            <magSubTopic>/mag</magSubTopic>
            <baroSubTopic>/baro</baroSubTopic>
            <mavlink_addr>INADDR_ANY</mavlink_addr>
            <mavlink_tcp_port>4560</mavlink_tcp_port>
            <mavlink_udp_port>14560</mavlink_udp_port>
            <serialEnabled>0</serialEnabled>
            <serialDevice>/dev/ttyACM0</serialDevice>
            <baudRate>921600</baudRate>
            <qgc_addr>INADDR_ANY</qgc_addr>
            <qgc_udp_port>14550</qgc_udp_port>
            <sdk_addr>INADDR_ANY</sdk_addr>
            <sdk_udp_port>14540</sdk_udp_port>
            <hil_mode>0</hil_mode>
            <hil_state_level>0</hil_state_level>
            <send_vision_estimation>0</send_vision_estimation>
            <send_odometry>1</send_odometry>
            <enable_lockstep>1</enable_lockstep>
            <use_tcp>1</use_tcp>
            <motorSpeedCommandPubTopic>/gazebo/command/motor_speed</motorSpeedCommandPubTopic>
            <control_channels>
                <channel name='rotor1'>
                    <input_index>0</input_index>
                    <input_offset>0</input_offset>
                    <input_scaling>1000</input_scaling>
                    <zero_position_disarmed>0</zero_position_disarmed>
                    <zero_position_armed>100</zero_position_armed>
                    <joint_control_type>velocity</joint_control_type>
                </channel>
                <channel name='rotor2'>
                    <input_index>1</input_index>
                    <input_offset>0</input_offset>
                    <input_scaling>1000</input_scaling>
                    <zero_position_disarmed>0</zero_position_disarmed>
                    <zero_position_armed>100</zero_position_armed>
                    <joint_control_type>velocity</joint_control_type>
                </channel>
                <channel name='rotor3'>
                    <input_index>2</input_index>
                    <input_offset>0</input_offset>
                    <input_scaling>1000</input_scaling>
                    <zero_position_disarmed>0</zero_position_disarmed>
                    <zero_position_armed>100</zero_position_armed>
                    <joint_control_type>velocity</joint_control_type>
                </channel>
                <channel name='rotor4'>
                    <input_index>3</input_index>
                    <input_offset>0</input_offset>
                    <input_scaling>1000</input_scaling>
                    <zero_position_disarmed>0</zero_position_disarmed>
                    <zero_position_armed>100</zero_position_armed>
                    <joint_control_type>velocity</joint_control_type>
                </channel>
                <channel name='rotor5'>
                    <input_index>4</input_index>
                    <input_offset>1</input_offset>
                    <input_scaling>324.6</input_scaling>
                    <zero_position_disarmed>0</zero_position_disarmed>
                    <zero_position_armed>0</zero_position_armed>
                    <joint_control_type>velocity</joint_control_type>
                    <joint_control_pid>
                        <p>0.1</p>
                        <i>0</i>
                        <d>0</d>
                        <iMax>0.0</iMax>
                        <iMin>0.0</iMin>
                        <cmdMax>2</cmdMax>
                        <cmdMin>-2</cmdMin>
                    </joint_control_pid>
                    <joint_name>zephyr_delta_wing::propeller_joint</joint_name>
                </channel>
                <channel name='rotor6'>
                    <input_index>5</input_index>
                    <input_offset>0</input_offset>
                    <input_scaling>0.524</input_scaling>
                    <zero_position_disarmed>0</zero_position_disarmed>
                    <zero_position_armed>0</zero_position_armed>
                    <joint_control_type>position</joint_control_type>
                    <joint_name>zephyr_delta_wing::flap_left_joint</joint_name>
                    <joint_control_pid>
                        <p>10.0</p>
                        <i>0</i>
                        <d>0</d>
                        <iMax>0</iMax>
                        <iMin>0</iMin>
                        <cmdMax>20</cmdMax>
                        <cmdMin>-20</cmdMin>
                    </joint_control_pid>
                </channel>
                <channel name='rotor7'>
                    <input_index>6</input_index>
                    <input_offset>0</input_offset>
                    <input_scaling>0.524</input_scaling>
                    <zero_position_disarmed>0</zero_position_disarmed>
                    <zero_position_armed>0</zero_position_armed>
                    <joint_control_type>position</joint_control_type>
                    <joint_name>zephyr_delta_wing::flap_right_joint</joint_name>
                    <joint_control_pid>
                        <p>10.0</p>
                        <i>0</i>
                        <d>0</d>
                        <iMax>0</iMax>
                        <iMin>0</iMin>
                        <cmdMax>20</cmdMax>
                        <cmdMin>-20</cmdMin>
                    </joint_control_pid>
                </channel>
                <channel name='rotor8'>
                    <input_index>7</input_index>
                    <input_offset>0</input_offset>
                    <input_scaling>0.524</input_scaling>
                    <zero_position_disarmed>0</zero_position_disarmed>
                    <zero_position_armed>0</zero_position_armed>
                    <joint_control_type>position</joint_control_type>
                </channel>
            </control_channels>
        </plugin>
        <static>0</static>
        <plugin name='rotors_gazebo_imu_plugin' filename='libgazebo_imu_plugin.so'>
            <robotNamespace/>
            <linkName>/imu_link</linkName>
            <imuTopic>/imu</imuTopic>
            <gyroscopeNoiseDensity>0.00018665</gyroscopeNoiseDensity>
            <gyroscopeRandomWalk>3.8785e-05</gyroscopeRandomWalk>
            <gyroscopeBiasCorrelationTime>1000.0</gyroscopeBiasCorrelationTime>
            <gyroscopeTurnOnBiasSigma>0.0087</gyroscopeTurnOnBiasSigma>
            <accelerometerNoiseDensity>0.00186</accelerometerNoiseDensity>
            <accelerometerRandomWalk>0.006</accelerometerRandomWalk>
            <accelerometerBiasCorrelationTime>300.0</accelerometerBiasCorrelationTime>
            <accelerometerTurnOnBiasSigma>0.196</accelerometerTurnOnBiasSigma>
        </plugin>
    </model>
</sdf>
